/*
 * Copyright (C) 2012 Typesafe Inc. <http://www.typesafe.com>
 */

package scala.async
package run
package exceptions

import scala.async.Async.{async, await}

import scala.concurrent.{future, ExecutionContext, Await}
import ExecutionContext.Implicits._
import scala.concurrent.duration._
import scala.reflect.ClassTag

import org.junit.Test

class ExceptionsSpec {

  @Test
  def `uncaught exception within async`() {
    val fut = async { throw new Exception("problem") }
    intercept[Exception] { Await.result(fut, 2.seconds) }
  }

  @Test
  def `uncaught exception within async after await`() {
    val base = future { "five!".length }
    val fut = async {
      val len = await(base)
      throw new Exception(s"illegal length: $len")
    }
    intercept[Exception] { Await.result(fut, 2.seconds) }
  }

  @Test
  def `await failing future within async`() {
    val base = future[Int] { throw new Exception("problem") }
    val fut = async {
      val x = await(base)
      x * 2
    }
    intercept[Exception] { Await.result(fut, 2.seconds) }
  }

  @Test
  def `await failing future within async after await`() {
    val base = future[Any] { "five!".length }
    val fut = async {
      val a = await(base.mapTo[Int])                          // result: 5
      val b = await((future { (a * 2).toString }).mapTo[Int]) // result: ClassCastException
      val c = await(future { (7 * 2).toString })              // result: "14"
      b + "-" + c
    }
    intercept[ClassCastException] { Await.result(fut, 2.seconds) }
  }

}
